Workbook

Sheet Ficha
A1: Ficha de jugador · comparador
A2: Elige un jugador en cada celda amarilla (desplegable) para compararlos.
A3: Jugador | B3: Axel Blaze | E3: Jugador | F3: Byron Love
A5: Posición | B5: =INDEX('IE1'!$C$3:$C$228,MATCH($B$3,'IE1'!$A$3:$A$228,0)) -> FW | E5: Posición | F5: =INDEX('IE1'!$C$3:$C$228,MATCH($F$3,'IE1'!$A$3:$A$228,0)) -> MF
A6: Size | B6: =INDEX('IE1'!$E$3:$E$228,MATCH($B$3,'IE1'!$A$3:$A$228,0)) -> Medium | E6: Size | F6: =INDEX('IE1'!$E$3:$E$228,MATCH($F$3,'IE1'!$A$3:$A$228,0)) -> Medium
A7: Elemento | B7: =INDEX('IE1'!$F$3:$F$228,MATCH($B$3,'IE1'!$A$3:$A$228,0)) -> Fire | E7: Elemento | F7: =INDEX('IE1'!$F$3:$F$228,MATCH($F$3,'IE1'!$A$3:$A$228,0)) -> Celestial
A8: Equipo | B8: =INDEX('IE1'!$I$3:$I$228,MATCH($B$3,'IE1'!$A$3:$A$228,0)) -> Raimon | E8: Equipo | F8: =INDEX('IE1'!$I$3:$I$228,MATCH($F$3,'IE1'!$A$3:$A$228,0)) -> Zeus
A9: Rareza | B9: =INDEX('IE1'!$J$3:$J$228,MATCH($B$3,'IE1'!$A$3:$A$228,0)) -> Legendario | E9: Rareza | F9: =INDEX('IE1'!$J$3:$J$228,MATCH($F$3,'IE1'!$A$3:$A$228,0)) -> Legendario
A12: Vida | B12: =MIN(1,C12/'Stats base'!B$30) -> 0.53636364 | C12: =INDEX('IE1'!$K$3:$K$228,MATCH($B$3,'IE1'!$A$3:$A$228,0)) -> 118 | E12: Vida | F12: =MIN(1,G12/'Stats base'!B$30) -> 0.69545455 | G12: =INDEX('IE1'!$K$3:$K$228,MATCH($F$3,'IE1'!$A$3:$A$228,0)) -> 153
A13: Ataque | B13: =MIN(1,C13/'Stats base'!C$30) -> 0.832 | C13: =INDEX('IE1'!$L$3:$L$228,MATCH($B$3,'IE1'!$A$3:$A$228,0)) -> 20.8 | E13: Ataque | F13: =MIN(1,G13/'Stats base'!C$30) -> 0.844 | G13: =INDEX('IE1'!$L$3:$L$228,MATCH($F$3,'IE1'!$A$3:$A$228,0)) -> 21.1
A14: Ataque especial | B14: =MIN(1,C14/'Stats base'!D$30) -> 0.85 | C14: =INDEX('IE1'!$M$3:$M$228,MATCH($B$3,'IE1'!$A$3:$A$228,0)) -> 34 | E14: Ataque especial | F14: =MIN(1,G14/'Stats base'!D$30) -> 0.885 | G14: =INDEX('IE1'!$M$3:$M$228,MATCH($F$3,'IE1'!$A$3:$A$228,0)) -> 35.4
A15: Defensa | B15: =MIN(1,C15/'Stats base'!E$30) -> 0.29333333 | C15: =INDEX('IE1'!$N$3:$N$228,MATCH($B$3,'IE1'!$A$3:$A$228,0)) -> 4.4 | E15: Defensa | F15: =MIN(1,G15/'Stats base'!E$30) -> 0.46666667 | G15: =INDEX('IE1'!$N$3:$N$228,MATCH($F$3,'IE1'!$A$3:$A$228,0)) -> 7
A16: Velocidad | B16: =MIN(1,C16/'Stats base'!F$30) -> 0.83571429 | C16: =INDEX('IE1'!$O$3:$O$228,MATCH($B$3,'IE1'!$A$3:$A$228,0)) -> 117 | E16: Velocidad | F16: =MIN(1,G16/'Stats base'!F$30) -> 0.87142857 | G16: =INDEX('IE1'!$O$3:$O$228,MATCH($F$3,'IE1'!$A$3:$A$228,0)) -> 122
A17: Regate | B17: =MIN(1,C17/'Stats base'!G$30) -> 0.45 | C17: =INDEX('IE1'!$P$3:$P$228,MATCH($B$3,'IE1'!$A$3:$A$228,0)) -> 0.045 | E17: Regate | F17: =MIN(1,G17/'Stats base'!G$30) -> 0.91 | G17: =INDEX('IE1'!$P$3:$P$228,MATCH($F$3,'IE1'!$A$3:$A$228,0)) -> 0.091

Sheet IE1
A1: Player info | H1: Cara, equipo y rareza | K1: Estadísticas iniciales
A2: Full Name | B2: Nickname | C2: Position | D2: Gender | E2: Size | F2: Element | G2: Player HEX ID | H2: Cara | I2: Equipo | J2: Rareza | K2: Vida | L2: Ataque | M2: Ataque especial | N2: Defensa | O2: Velocidad | P2: Regate
A3: Mark Evans | B3: Mark | C3: GK | D3: Male | E3: Medium | F3: Celestial | G3: 0x01 | I3: Raimon | J3: Legendario | K3: =ROUND(INDEX('Stats base'!B$5:B$8,MATCH($C3,'Stats base'!$A$5:$A$8,0))*INDEX('Stats base'!B$12:B$14,MATCH($E3,'Stats base'!$A$12:$A$14,0))*INDEX('Stats base'!B$18:B$22,MATCH($J3,'Stats base'!$A$18:$A$22,0))*IFERROR(INDEX(Variación!C$3:C$228,MATCH($G3,Variación!$A$3:$A$228,0)),1),0) -> 200 | L3: =ROUND(INDEX('Stats base'!C$5:C$8,MATCH($C3,'Stats base'!$A$5:$A$8,0))*INDEX('Stats base'!C$12:C$14,MATCH($E3,'Stats base'!$A$12:$A$14,0))*INDEX('Stats base'!C$18:C$22,MATCH($J3,'Stats base'!$A$18:$A$22,0))*IFERROR(INDEX(Variación!D$3:D$228,MATCH($G3,Variación!$A$3:$A$228,0)),1),1) -> 17.7 | M3: =ROUND(INDEX('Stats base'!D$5:D$8,MATCH($C3,'Stats base'!$A$5:$A$8,0))*INDEX('Stats base'!D$12:D$14,MATCH($E3,'Stats base'!$A$12:$A$14,0))*INDEX('Stats base'!D$18:D$22,MATCH($J3,'Stats base'!$A$18:$A$22,0))*IFERROR(INDEX(Variación!E$3:E$228,MATCH($G3,Variación!$A$3:$A$228,0)),1),1) -> 36.7 | N3: =ROUND(INDEX('Stats base'!E$5:E$8,MATCH($C3,'Stats base'!$A$5:$A$8,0))*INDEX('Stats base'!E$12:E$14,MATCH($E3,'Stats base'!$A$12:$A$14,0))*INDEX('Stats base'!E$18:E$22,MATCH($J3,'Stats base'!$A$18:$A$22,0))*IFERROR(INDEX(Variación!F$3:F$228,MATCH($G3,Variación!$A$3:$A$228,0)),1),1) -> 12.9 | O3: =ROUND(INDEX('Stats base'!F$5:F$8,MATCH($C3,'Stats base'!$A$5:$A$8,0))*INDEX('Stats base'!F$12:F$14,MATCH($E3,'Stats base'!$A$12:$A$14,0))*INDEX('Stats base'!F$18:F$22,MATCH($J3,'Stats base'!$A$18:$A$22,0))*IFERROR(INDEX(Variación!G$3:G$228,MATCH($G3,Variación!$A$3:$A$228,0)),1),0) -> 96 | P3: =MIN('Stats base'!$G$30,ROUND(INDEX('Stats base'!G$5:G$8,MATCH($C3,'Stats base'!$A$5:$A$8,0))*INDEX('Stats base'!G$12:G$14,MATCH($E3,'Stats base'!$A$12:$A$14,0))*INDEX('Stats base'!G$18:G$22,MATCH($J3,'Stats base'!$A$18:$A$22,0))*IFERROR(INDEX(Variación!H$3:H$228,MATCH($G3,Variación!$A$3:$A$228,0)),1),3)) -> 0.018
A4: Nathan Swift | B4: Nathan | C4: DF | D4: Male | E4: Medium | F4: Air | G4: 0x02 | I4: Raimon | J4: Legendario | K4: =ROUND(INDEX('Stats base'!B$5:B$8,MATCH($C4,'Stats base'!$A$5:$A$8,0))*INDEX('Stats base'!B$12:B$14,MATCH($E4,'Stats base'!$A$12:$A$14,0))*INDEX('Stats base'!B$18:B$22,MATCH($J4,'Stats base'!$A$18:$A$22,0))*IFERROR(INDEX(Variación!C$3:C$228,MATCH($G4,Variación!$A$3:$A$228,0)),1),0) -> 184 | L4: =ROUND(INDEX('Stats base'!C$5:C$8,MATCH($C4,'Stats base'!$A$5:$A$8,0))*INDEX('Stats base'!C$12:C$14,MATCH($E4,'Stats base'!$A$12:$A$14,0))*INDEX('Stats base'!C$18:C$22,MATCH($J4,'Stats base'!$A$18:$A$22,0))*IFERROR(INDEX(Variación!D$3:D$228,MATCH($G4,Variación!$A$3:$A$228,0)),1),1) -> 11.3 | M4: =ROUND(INDEX('Stats base'!D$5:D$8,MATCH($C4,'Stats base'!$A$5:$A$8,0))*INDEX('Stats base'!D$12:D$14,MATCH($E4,'Stats base'!$A$12:$A$14,0))*INDEX('Stats base'!D$18:D$22,MATCH($J4,'Stats base'!$A$18:$A$22,0))*IFERROR(INDEX(Variación!E$3:E$228,MATCH($G4,Variación!$A$3:$A$228,0)),1),1) -> 19.4 | N4: =ROUND(INDEX('Stats base'!E$5:E$8,MATCH($C4,'Stats base'!$A$5:$A$8,0))*INDEX('Stats base'!E$12:E$14,MATCH($E4,'Stats base'!$A$12:$A$14,0))*INDEX('Stats base'!E$18:E$22,MATCH($J4,'Stats base'!$A$18:$A$22,0))*IFERROR(INDEX(Variación!F$3:F$228,MATCH($G4,Variación!$A$3:$A$228,0)),1),1) -> 12.4 | O4: =ROUND(INDEX('Stats base'!F$5:F$8,MATCH($C4,'Stats base'!$A$5:$A$8,0))*INDEX('Stats base'!F$12:F$14,MATCH($E4,'Stats base'!$A$12:$A$14,0))*INDEX('Stats base'!F$18:F$22,MATCH($J4,'Stats base'!$A$18:$A$22,0))*IFERROR(INDEX(Variación!G$3:G$228,MATCH($G4,Variación!$A$3:$A$228,0)),1),0) -> 114 | P4: =MIN('Stats base'!$G$30,ROUND(INDEX('Stats base'!G$5:G$8,MATCH($C4,'Stats base'!$A$5:$A$8,0))*INDEX('Stats base'!G$12:G$14,MATCH($E4,'Stats base'!$A$12:$A$14,0))*INDEX('Stats base'!G$18:G$22,MATCH($J4,'Stats base'!$A$18:$A$22,0))*IFERROR(INDEX(Variación!H$3:H$228,MATCH($G4,Variación!$A$3:$A$228,0)),1),3)) -> 0.03
A5: Jack Wallside | B5: Jack | C5: DF | D5: Male | E5: Large | F5: Earth | G5: 0x03 | I5: Raimon | J5: Épico | K5: =ROUND(INDEX('Stats base'!B$5:B$8,MATCH($C5,'Stats base'!$A$5:$A$8,0))*INDEX('Stats base'!B$12:B$14,MATCH($E5,'Stats base'!$A$12:$A$14,0))*INDEX('Stats base'!B$18:B$22,MATCH($J5,'Stats base'!$A$18:$A$22,0))*IFERROR(INDEX(Variación!C$3:C$228,MATCH($G5,Variación!$A$3:$A$228,0)),1),0) -> 205 | L5: =ROUND(INDEX('Stats base'!C$5:C$8,MATCH($C5,'Stats base'!$A$5:$A$8,0))*INDEX('Stats base'!C$12:C$14,MATCH($E5,'Stats base'!$A$12:$A$14,0))*INDEX('Stats base'!C$18:C$22,MATCH($J5,'Stats base'!$A$18:$A$22,0))*IFERROR(INDEX(Variación!D$3:D$228,MATCH($G5,Variación!$A$3:$A$228,0)),1),1) -> 10.1 | M5: =ROUND(INDEX('Stats base'!D$5:D$8,MATCH($C5,'Stats base'!$A$5:$A$8,0))*INDEX('Stats base'!D$12:D$14,MATCH($E5,'Stats base'!$A$12:$A$14,0))*INDEX('Stats base'!D$18:D$22,MATCH($J5,'Stats base'!$A$18:$A$22,0))*IFERROR(INDEX(Variación!E$3:E$228,MATCH($G5,Variación!$A$3:$A$228,0)),1),1) -> 16.4 | N5: =ROUND(INDEX('Stats base'!E$5:E$8,MATCH($C5,'Stats base'!$A$5:$A$8,0))*INDEX('Stats base'!E$12:E$14,MATCH($E5,'Stats base'!$A$12:$A$14,0))*INDEX('Stats base'!E$18:E$22,MATCH($J5,'Stats base'!$A$18:$A$22,0))*IFERROR(INDEX(Variación!F$3:F$228,MATCH($G5,Variación!$A$3:$A$228,0)),1),1) -> 13.8 | O5: =ROUND(INDEX('Stats base'!F$5:F$8,MATCH($C5,'Stats base'!$A$5:$A$8,0))*INDEX('Stats base'!F$12:F$14,MATCH($E5,'Stats base'!$A$12:$A$14,0))*INDEX('Stats base'!F$18:F$22,MATCH($J5,'Stats base'!$A$18:$A$22,0))*IFERROR(INDEX(Variación!G$3:G$228,MATCH($G5,Variación!$A$3:$A$228,0)),1),0) -> 82 | P5: =MIN('Stats base'!$G$30,ROUND(INDEX('Stats base'!G$5:G$8,MATCH($C5,'Stats base'!$A$5:$A$8,0))*INDEX('Stats base'!G$12:G$14,MATCH($E5,'Stats base'!$A$12:$A$14,0))*INDEX('Stats base'!G$18:G$22,MATCH($J5,'Stats base'!$A$18:$A$22,0))*IFERROR(INDEX(Variación!H$3:H$228,MATCH($G5,Variación!$A$3:$A$228,0)),1),3)) -> 0.017
A6: Jim Wraith | B6: Jim | C6: DF | D6: Male | E6: Medium | F6: Wood | G6: 0x04 | I6: Raimon | J6: Poco Común | K6: =ROUND(INDEX('Stats base'!B$5:B$8,MATCH($C6,'Stats base'!$A$5:$A$8,0))*INDEX('Stats base'!B$12:B$14,MATCH($E6,'Stats base'!$A$12:$A$14,0))*INDEX('Stats base'!B$18:B$22,MATCH($J6,'Stats base'!$A$18:$A$22,0))*IFERROR(INDEX(Variación!C$3:C$228,MATCH($G6,Variación!$A$3:$A$228,0)),1),0) -> 142 | L6: =ROUND(INDEX('Stats base'!C$5:C$8,MATCH($C6,'Stats base'!$A$5:$A$8,0))*INDEX('Stats base'!C$12:C$14,MATCH($E6,'Stats base'!$A$12:$A$14,0))*INDEX('Stats base'!C$18:C$22,MATCH($J6,'Stats base'!$A$18:$A$22,0))*IFERROR(INDEX(Variación!D$3:D$228,MATCH($G6,Variación!$A$3:$A$228,0)),1),1) -> 7.4 | M6: =ROUND(INDEX('Stats base'!D$5:D$8,MATCH($C6,'Stats base'!$A$5:$A$8,0))*INDEX('Stats base'!D$12:D$14,MATCH($E6,'Stats base'!$A$12:$A$14,0))*INDEX('Stats base'!D$18:D$22,MATCH($J6,'Stats base'!$A$18:$A$22,0))*IFERROR(INDEX(Variación!E$3:E$228,MATCH($G6,Variación!$A$3:$A$228,0)),1),1) -> 13.3 | N6: =ROUND(INDEX('Stats base'!E$5:E$8,MATCH($C6,'Stats base'!$A$5:$A$8,0))*INDEX('Stats base'!E$12:E$14,MATCH($E6,'Stats base'!$A$12:$A$14,0))*INDEX('Stats base'!E$18:E$22,MATCH($J6,'Stats base'!$A$18:$A$22,0))*IFERROR(INDEX(Variación!F$3:F$228,MATCH($G6,Variación!$A$3:$A$228,0)),1),1) -> 8.1 | O6: =ROUND(INDEX('Stats base'!F$5:F$8,MATCH($C6,'Stats base'!$A$5:$A$8,0))*INDEX('Stats base'!F$12:F$14,MATCH($E6,'Stats base'!$A$12:$A$14,0))*INDEX('Stats base'!F$18:F$22,MATCH($J6,'Stats base'!$A$18:$A$22,0))*IFERROR(INDEX(Variación!G$3:G$228,MATCH($G6,Variación!$A$3:$A$228,0)),1),0) -> 100 | P6: =MIN('Stats base'!$G$30,ROUND(INDEX('Stats base'!G$5:G$8,MATCH($C6,'Stats base'!$A$5:$A$8,0))*INDEX('Stats base'!G$12:G$14,MATCH($E6,'Stats base'!$A$12:$A$14,0))*INDEX('Stats base'!G$18:G$22,MATCH($J6,'Stats base'!$A$18:$A$22,0))*IFERROR(INDEX(Variación!H$3:H$228,MATCH($G6,Variación!$A$3:$A$228,0)),1),3)) -> 0.016
A7: Tod Ironside | B7: Tod | C7: DF | D7: Male | E7: Small | F7: Fire | G7: 0x05 | I7: Raimon | J7: Poco Común | K7: =ROUND(INDEX('Stats base'!B$5:B$8,MATCH($C7,'Stats base'!$A$5:$A$8,0))*INDEX('Stats base'!B$12:B$14,MATCH($E7,'Stats base'!$A$12:$A$14,0))*INDEX('Stats base'!B$18:B$22,MATCH($J7,'Stats base'!$A$18:$A$22,0))*IFERROR(INDEX(Variación!C$3:C$228,MATCH($G7,Variación!$A$3:$A$228,0)),1),0) -> 137 | L7: =ROUND(INDEX('Stats base'!C$5:C$8,MATCH($C7,'Stats base'!$A$5:$A$8,0))*INDEX('Stats base'!C$12:C$14,MATCH($E7,'Stats base'!$A$12:$A$14,0))*INDEX('Stats base'!C$18:C$22,MATCH($J7,'Stats base'!$A$18:$A$22,0))*IFERROR(INDEX(Variación!D$3:D$228,MATCH($G7,Variación!$A$3:$A$228,0)),1),1) -> 7.9 | M7: =ROUND(INDEX('Stats base'!D$5:D$8,MATCH($C7,'Stats base'!$A$5:$A$8,0))*INDEX('Stats base'!D$12:D$14,MATCH($E7,'Stats base'!$A$12:$A$14,0))*INDEX('Stats base'!D$18:D$22,MATCH($J7,'Stats base'!$A$18:$A$22,0))*IFERROR(INDEX(Variación!E$3:E$228,MATCH($G7,Variación!$A$3:$A$228,0)),1),1) -> 12.9 | N7: =ROUND(INDEX('Stats base'!E$5:E$8,MATCH($C7,'Stats base'!$A$5:$A$8,0))*INDEX('Stats base'!E$12:E$14,MATCH($E7,'Stats base'!$A$12:$A$14,0))*INDEX('Stats base'!E$18:E$22,MATCH($J7,'Stats base'!$A$18:$A$22,0))*IFERROR(INDEX(Variación!F$3:F$228,MATCH($G7,Variación!$A$3:$A$228,0)),1),1) -> 9.2 | O7: =ROUND(INDEX('Stats base'!F$5:F$8,MATCH($C7,'Stats base'!$A$5:$A$8,0))*INDEX('Stats base'!F$12:F$14,MATCH($E7,'Stats base'!$A$12:$A$14,0))*INDEX('Stats base'!F$18:F$22,MATCH($J7,'Stats base'!$A$18:$A$22,0))*IFERROR(INDEX(Variación!G$3:G$228,MATCH($G7,Variación!$A$3:$A$228,0)),1),0) -> 100 | P7: =MIN('Stats base'!$G$30,ROUND(INDEX('Stats base'!G$5:G$8,MATCH($C7,'Stats base'!$A$5:$A$8,0))*INDEX('Stats base'!G$12:G$14,MATCH($E7,'Stats base'!$A$12:$A$14,0))*INDEX('Stats base'!G$18:G$22,MATCH($J7,'Stats base'!$A$18:$A$22,0))*IFERROR(INDEX(Variación!H$3:H$228,MATCH($G7,Variación!$A$3:$A$228,0)),1),3)) -> 0.018
A8: Steve Grim | B8: Steve | C8: MF | D8: Male | E8: Medium | F8: Air | G8: 0x06 | I8: Raimon | J8: Poco Común | K8: =ROUND(INDEX('Stats base'!B$5:B$8,MATCH($C8,'Stats base'!$A$5:$A$8,0))*INDEX('Stats base'!B$12:B$14,MATCH($E8,'Stats base'!$A$12:$A$14,0))*INDEX('Stats base'!B$18:B$22,MATCH($J8,'Stats base'!$A$18:$A$22,0))*IFERROR(INDEX(Variación!C$3:C$228,MATCH($G8,Variación!$A$3:$A$228,0)),1),0) -> 99 | L8: =ROUND(INDEX('Stats base'!C$5:C$8,MATCH($C8,'Stats base'!$A$5:$A$8,0))*INDEX('Stats base'!C$12:C$14,MATCH($E8,'Stats base'!$A$12:$A$14,0))*INDEX('Stats base'!C$18:C$22,MATCH($J8,'Stats base'!$A$18:$A$22,0))*IFERROR(INDEX(Variación!D$3:D$228,MATCH($G8,Variación!$A$3:$A$228,0)),1),1) -> 11 | M8: =ROUND(INDEX('Stats base'!D$5:D$8,MATCH($C8,'Stats base'!$A$5:$A$8,0))*INDEX('Stats base'!D$12:D$14,MATCH($E8,'Stats base'!$A$12:$A$14,0))*INDEX('Stats base'!D$18:D$22,MATCH($J8,'Stats base'!$A$18:$A$22,0))*IFERROR(INDEX(Variación!E$3:E$228,MATCH($G8,Variación!$A$3:$A$228,0)),1),1) -> 19.7 | N8: =ROUND(INDEX('Stats base'!E$5:E$8,MATCH($C8,'Stats base'!$A$5:$A$8,0))*INDEX('Stats base'!E$12:E$14,MATCH($E8,'Stats base'!$A$12:$A$14,0))*INDEX('Stats base'!E$18:E$22,MATCH($J8,'Stats base'!$A$18:$A$22,0))*IFERROR(INDEX(Variación!F$3:F$228,MATCH($G8,Variación!$A$3:$A$228,0)),1),1) -> 4.4 | O8: =ROUND(INDEX('Stats base'!F$5:F$8,MATCH($C8,'Stats base'!$A$5:$A$8,0))*INDEX('Stats base'!F$12:F$14,MATCH($E8,'Stats base'!$A$12:$A$14,0))*INDEX('Stats base'!F$18:F$22,MATCH($J8,'Stats base'!$A$18:$A$22,0))*IFERROR(INDEX(Variación!G$3:G$228,MATCH($G8,Variación!$A$3:$A$228,0)),1),0) -> 110 | P8: =MIN('Stats base'!$G$30,ROUND(INDEX('Stats base'!G$5:G$8,MATCH($C8,'Stats base'!$A$5:$A$8,0))*INDEX('Stats base'!G$12:G$14,MATCH($E8,'Stats base'!$A$12:$A$14,0))*INDEX('Stats base'!G$18:G$22,MATCH($J8,'Stats base'!$A$18:$A$22,0))*IFERROR(INDEX(Variación!H$3:H$228,MATCH($G8,Variación!$A$3:$A$228,0)),1),3)) -> 0.042
A9: Tim Saunders | B9: Timmy | C9: MF | D9: Male | E9: Small | F9: Dragon | G9: 0x07 | I9: Raimon | J9: Poco Común | K9: =ROUND(INDEX('Stats base'!B$5:B$8,MATCH($C9,'Stats base'!$A$5:$A$8,0))*INDEX('Stats base'!B$12:B$14,MATCH($E9,'Stats base'!$A$12:$A$14,0))*INDEX('Stats base'!B$18:B$22,MATCH($J9,'Stats base'!$A$18:$A$22,0))*IFERROR(INDEX(Variación!C$3:C$228,MATCH($G9,Variación!$A$3:$A$228,0)),1),0) -> 90 | L9: =ROUND(INDEX('Stats base'!C$5:C$8,MATCH($C9,'Stats base'!$A$5:$A$8,0))*INDEX('Stats base'!C$12:C$14,MATCH($E9,'Stats base'!$A$12:$A$14,0))*INDEX('Stats base'!C$18:C$22,MATCH($J9,'Stats base'!$A$18:$A$22,0))*IFERROR(INDEX(Variación!D$3:D$228,MATCH($G9,Variación!$A$3:$A$228,0)),1),1) -> 10.2 | M9: =ROUND(INDEX('Stats base'!D$5:D$8,MATCH($C9,'Stats base'!$A$5:$A$8,0))*INDEX('Stats base'!D$12:D$14,MATCH($E9,'Stats base'!$A$12:$A$14,0))*INDEX('Stats base'!D$18:D$22,MATCH($J9,'Stats base'!$A$18:$A$22,0))*IFERROR(INDEX(Variación!E$3:E$228,MATCH($G9,Variación!$A$3:$A$228,0)),1),1) -> 17.4 | N9: =ROUND(INDEX('Stats base'!E$5:E$8,MATCH($C9,'Stats base'!$A$5:$A$8,0))*INDEX('Stats base'!E$12:E$14,MATCH($E9,'Stats base'!$A$12:$A$14,0))*INDEX('Stats base'!E$18:E$22,MATCH($J9,'Stats base'!$A$18:$A$22,0))*IFERROR(INDEX(Variación!F$3:F$228,MATCH($G9,Variación!$A$3:$A$228,0)),1),1) -> 4.1 | O9: =ROUND(INDEX('Stats base'!F$5:F$8,MATCH($C9,'Stats base'!$A$5:$A$8,0))*INDEX('Stats base'!F$12:F$14,MATCH($E9,'Stats base'!$A$12:$A$14,0))*INDEX('Stats base'!F$18:F$22,MATCH($J9,'Stats base'!$A$18:$A$22,0))*IFERROR(INDEX(Variación!G$3:G$228,MATCH($G9,Variación!$A$3:$A$228,0)),1),0) -> 114 | P9: =MIN('Stats base'!$G$30,ROUND(INDEX('Stats base'!G$5:G$8,MATCH($C9,'Stats base'!$A$5:$A$8,0))*INDEX('Stats base'!G$12:G$14,MATCH($E9,'Stats base'!$A$12:$A$14,0))*INDEX('Stats base'!G$18:G$22,MATCH($J9,'Stats base'!$A$18:$A$22,0))*IFERROR(INDEX(Variación!H$3:H$228,MATCH($G9,Variación!$A$3:$A$228,0)),1),3)) -> 0.046
A10: Sam Kincaid | B10: Sam | C10: MF | D10: Male | E10: Medium | F10: Fire | G10: 0x08 | I10: Raimon | J10: Poco Común | K10: =ROUND(INDEX('Stats base'!B$5:B$8,MATCH($C10,'Stats base'!$A$5:$A$8,0))*INDEX('Stats base'!B$12:B$14,MATCH($E10,'Stats base'!$A$12:$A$14,0))*INDEX('Stats base'!B$18:B$22,MATCH($J10,'Stats base'!$A$18:$A$22,0))*IFERROR(INDEX(Variación!C$3:C$228,MATCH($G10,Variación!$A$3:$A$228,0)),1),0) -> 89 | L10: =ROUND(INDEX('Stats base'!C$5:C$8,MATCH($C10,'Stats base'!$A$5:$A$8,0))*INDEX('Stats base'!C$12:C$14,MATCH($E10,'Stats base'!$A$12:$A$14,0))*INDEX('Stats base'!C$18:C$22,MATCH($J10,'Stats base'!$A$18:$A$22,0))*IFERROR(INDEX(Variación!D$3:D$228,MATCH($G10,Variación!$A$3:$A$228,0)),1),1) -> 10.2 | M10: =ROUND(INDEX('Stats base'!D$5:D$8,MATCH($C10,'Stats base'!$A$5:$A$8,0))*INDEX('Stats base'!D$12:D$14,MATCH($E10,'Stats base'!$A$12:$A$14,0))*INDEX('Stats base'!D$18:D$22,MATCH($J10,'Stats base'!$A$18:$A$22,0))*IFERROR(INDEX(Variación!E$3:E$228,MATCH($G10,Variación!$A$3:$A$228,0)),1),1) -> 16.3 | N10: =ROUND(INDEX('Stats base'!E$5:E$8,MATCH($C10,'Stats base'!$A$5:$A$8,0))*INDEX('Stats base'!E$12:E$14,MATCH($E10,'Stats base'!$A$12:$A$14,0))*INDEX('Stats base'!E$18:E$22,MATCH($J10,'Stats base'!$A$18:$A$22,0))*IFERROR(INDEX(Variación!F$3:F$228,MATCH($G10,Variación!$A$3:$A$228,0)),1),1) -> 4.1 | O10: =ROUND(INDEX('Stats base'!F$5:F$8,MATCH($C10,'Stats base'!$A$5:$A$8,0))*INDEX('Stats base'!F$12:F$14,MATCH($E10,'Stats base'!$A$12:$A$14,0))*INDEX('Stats base'!F$18:F$22,MATCH($J10,'Stats base'!$A$18:$A$22,0))*IFERROR(INDEX(Variación!G$3:G$228,MATCH($G10,Variación!$A$3:$A$228,0)),1),0) -> 111 | P10: =MIN('Stats base'!$G$30,ROUND(INDEX('Stats base'!G$5:G$8,MATCH($C10,'Stats base'!$A$5:$A$8,0))*INDEX('Stats base'!G$12:G$14,MATCH($E10,'Stats base'!$A$12:$A$14,0))*INDEX('Stats base'!G$18:G$22,MATCH($J10,'Stats base'!$A$18:$A$22,0))*IFERROR(INDEX(Variación!H$3:H$228,MATCH($G10,Variación!$A$3:$A$228,0)),1),3)) -> 0.046
A11: Maxwell Carson | B11: Max | C11: FW | D11: Male | E11: Medium | F11: Air | G11: 0x09 | I11: Raimon | J11: Raro | K11: =ROUND(INDEX('Stats base'!B$5:B$8,MATCH($C11,'Stats base'!$A$5:$A$8,0))*INDEX('Stats base'!B$12:B$14,MATCH($E11,'Stats base'!$A$12:$A$14,0))*INDEX('Stats base'!B$18:B$22,MATCH($J11,'Stats base'!$A$18:$A$22,0))*IFERROR(INDEX(Variación!C$3:C$228,MATCH($G11,Variación!$A$3:$A$228,0)),1),0) -> 102 | L11: =ROUND(INDEX('Stats base'!C$5:C$8,MATCH($C11,'Stats base'!$A$5:$A$8,0))*INDEX('Stats base'!C$12:C$14,MATCH($E11,'Stats base'!$A$12:$A$14,0))*INDEX('Stats base'!C$18:C$22,MATCH($J11,'Stats base'!$A$18:$A$22,0))*IFERROR(INDEX(Variación!D$3:D$228,MATCH($G11,Variación!$A$3:$A$228,0)),1),1) -> 15.3 | M11: =ROUND(INDEX('Stats base'!D$5:D$8,MATCH($C11,'Stats base'!$A$5:$A$8,0))*INDEX('Stats base'!D$12:D$14,MATCH($E11,'Stats base'!$A$12:$A$14,0))*INDEX('Stats base'!D$18:D$22,MATCH($J11,'Stats base'!$A$18:$A$22,0))*IFERROR(INDEX(Variación!E$3:E$228,MATCH($G11,Variación!$A$3:$A$228,0)),1),1) -> 23 | N11: =ROUND(INDEX('Stats base'!E$5:E$8,MATCH($C11,'Stats base'!$A$5:$A$8,0))*INDEX('Stats base'!E$12:E$14,MATCH($E11,'Stats base'!$A$12:$A$14,0))*INDEX('Stats base'!E$18:E$22,MATCH($J11,'Stats base'!$A$18:$A$22,0))*IFERROR(INDEX(Variación!F$3:F$228,MATCH($G11,Variación!$A$3:$A$228,0)),1),1) -> 3.9 | O11: =ROUND(INDEX('Stats base'!F$5:F$8,MATCH($C11,'Stats base'!$A$5:$A$8,0))*INDEX('Stats base'!F$12:F$14,MATCH($E11,'Stats base'!$A$12:$A$14,0))*INDEX('Stats base'!F$18:F$22,MATCH($J11,'Stats base'!$A$18:$A$22,0))*IFERROR(INDEX(Variación!G$3:G$228,MATCH($G11,Variación!$A$3:$A$228,0)),1),0) -> 107 | P11: =MIN('Stats base'!$G$30,ROUND(INDEX('Stats base'!G$5:G$8,MATCH($C11,'Stats base'!$A$5:$A$8,0))*INDEX('Stats base'!G$12:G$14,MATCH($E11,'Stats base'!$A$12:$A$14,0))*INDEX('Stats base'!G$18:G$22,MATCH($J11,'Stats base'!$A$18:$A$22,0))*IFERROR(INDEX(Variación!H$3:H$228,MATCH($G11,Variación!$A$3:$A$228,0)),1),3)) -> 0.031
A12: Axel Blaze | B12: Axel | C12: FW | D12: Male | E12: Medium | F12: Fire | G12: 0x0A | I12: Raimon | J12: Legendario | K12: =ROUND(INDEX('Stats base'!B$5:B$8,MATCH($C12,'Stats base'!$A$5:$A$8,0))*INDEX('Stats base'!B$12:B$14,MATCH($E12,'Stats base'!$A$12:$A$14,0))*INDEX('Stats base'!B$18:B$22,MATCH($J12,'Stats base'!$A$18:$A$22,0))*IFERROR(INDEX(Variación!C$3:C$228,MATCH($G12,Variación!$A$3:$A$228,0)),1),0) -> 118 | L12: =ROUND(INDEX('Stats base'!C$5:C$8,MATCH($C12,'Stats base'!$A$5:$A$8,0))*INDEX('Stats base'!C$12:C$14,MATCH($E12,'Stats base'!$A$12:$A$14,0))*INDEX('Stats base'!C$18:C$22,MATCH($J12,'Stats base'!$A$18:$A$22,0))*IFERROR(INDEX(Variación!D$3:D$228,MATCH($G12,Variación!$A$3:$A$228,0)),1),1) -> 20.8 | M12: =ROUND(INDEX('Stats base'!D$5:D$8,MATCH($C12,'Stats base'!$A$5:$A$8,0))*INDEX('Stats base'!D$12:D$14,MATCH($E12,'Stats base'!$A$12:$A$14,0))*INDEX('Stats base'!D$18:D$22,MATCH($J12,'Stats base'!$A$18:$A$22,0))*IFERROR(INDEX(Variación!E$3:E$228,MATCH($G12,Variación!$A$3:$A$228,0)),1),1) -> 34 | N12: =ROUND(INDEX('Stats base'!E$5:E$8,MATCH($C12,'Stats base'!$A$5:$A$8,0))*INDEX('Stats base'!E$12:E$14,MATCH($E12,'Stats base'!$A$12:$A$14,0))*INDEX('Stats base'!E$18:E$22,MATCH($J12,'Stats base'!$A$18:$A$22,0))*IFERROR(INDEX(Variación!F$3:F$228,MATCH($G12,Variación!$A$3:$A$228,0)),1),1) -> 4.4 | O12: =ROUND(INDEX('Stats base'!F$5:F$8,MATCH($C12,'Stats base'!$A$5:$A$8,0))*INDEX('Stats base'!F$12:F$14,MATCH($E12,'Stats base'!$A$12:$A$14,0))*INDEX('Stats base'!F$18:F$22,MATCH($J12,'Stats base'!$A$18:$A$22,0))*IFERROR(INDEX(Variación!G$3:G$228,MATCH($G12,Variación!$A$3:$A$228,0)),1),0) -> 117 | P12: =MIN('Stats base'!$G$30,ROUND(INDEX('Stats base'!G$5:G$8,MATCH($C12,'Stats base'!$A$5:$A$8,0))*INDEX('Stats base'!G$12:G$14,MATCH($E12,'Stats base'!$A$12:$A$14,0))*INDEX('Stats base'!G$18:G$22,MATCH($J12,'Stats base'!$A$18:$A$22,0))*IFERROR(INDEX(Variación!H$3:H$228,MATCH($G12,Variación!$A$3:$A$228,0)),1),3)) -> 0.045
A13: Kevin Dragonfly | B13: Kevin | C13: FW | D13: Male | E13: Medium | F13: Dragon | G13: 0x0B | I13: Raimon | J13: Épico | K13: =ROUND(INDEX('Stats base'!B$5:B$8,MATCH($C13,'Stats base'!$A$5:$A$8,0))*INDEX('Stats base'!B$12:B$14,MATCH($E13,'Stats base'!$A$12:$A$14,0))*INDEX('Stats base'!B$18:B$22,MATCH($J13,'Stats base'!$A$18:$A$22,0))*IFERROR(INDEX(Variación!C$3:C$228,MATCH($G13,Variación!$A$3:$A$228,0)),1),0) -> 105 | L13: =ROUND(INDEX('Stats base'!C$5:C$8,MATCH($C13,'Stats base'!$A$5:$A$8,0))*INDEX('Stats base'!C$12:C$14,MATCH($E13,'Stats base'!$A$12:$A$14,0))*INDEX('Stats base'!C$18:C$22,MATCH($J13,'Stats base'!$A$18:$A$22,0))*IFERROR(INDEX(Variación!D$3:D$228,MATCH($G13,Variación!$A$3:$A$228,0)),1),1) -> 18.3 | M13: =ROUND(INDEX('Stats base'!D$5:D$8,MATCH($C13,'Stats base'!$A$5:$A$8,0))*INDEX('Stats base'!D$12:D$14,MATCH($E13,'Stats base'!$A$12:$A$14,0))*INDEX('Stats base'!D$18:D$22,MATCH($J13,'Stats base'!$A$18:$A$22,0))*IFERROR(INDEX(Variación!E$3:E$228,MATCH($G13,Variación!$A$3:$A$228,0)),1),1) -> 29.6 | N13: =ROUND(INDEX('Stats base'!E$5:E$8,MATCH($C13,'Stats base'!$A$5:$A$8,0))*INDEX('Stats base'!E$12:E$14,MATCH($E13,'Stats base'!$A$12:$A$14,0))*INDEX('Stats base'!E$18:E$22,MATCH($J13,'Stats base'!$A$18:$A$22,0))*IFERROR(INDEX(Variación!F$3:F$228,MATCH($G13,Variación!$A$3:$A$228,0)),1),1) -> 3.9 | O13: =ROUND(INDEX('Stats base'!F$5:F$8,MATCH($C13,'Stats base'!$A$5:$A$8,0))*INDEX('Stats base'!F$12:F$14,MATCH($E13,'Stats base'!$A$12:$A$14,0))*INDEX('Stats base'!F$18:F$22,MATCH($J13,'Stats base'!$A$18:$A$22,0))*IFERROR(INDEX(Variación!G$3:G$228,MATCH($G13,Variación!$A$3:$A$228,0)),1),0) -> 117 | P13: =MIN('Stats base'!$G$30,ROUND(INDEX('Stats base'!G$5:G$8,MATCH($C13,'Stats base'!$A$5:$A$8,0))*INDEX('Stats base'!G$12:G$14,MATCH($E13,'Stats base'!$A$12:$A$14,0))*INDEX('Stats base'!G$18:G$22,MATCH($J13,'Stats base'!$A$18:$A$22,0))*IFERROR(INDEX(Variación!H$3:H$228,MATCH($G13,Variación!$A$3:$A$228,0)),1),3)) -> 0.039
A14: William Glass | B14: Willy | C14: FW | D14: Male | E14: Medium | F14: Celestial | G14: 0x0C | I14: Raimon | J14: Raro | K14: =ROUND(INDEX('Stats base'!B$5:B$8,MATCH($C14,'Stats base'!$A$5:$A$8,0))*INDEX('Stats base'!B$12:B$14,MATCH($E14,'Stats base'!$A$12:$A$14,0))*INDEX('Stats base'!B$18:B$22,MATCH($J14,'Stats base'!$A$18:$A$22,0))*IFERROR(INDEX(Variación!C$3:C$228,MATCH($G14,Variación!$A$3:$A$228,0)),1),0) -> 83 | L14: =ROUND(INDEX('Stats base'!C$5:C$8,MATCH($C14,'Stats base'!$A$5:$A$8,0))*INDEX('Stats base'!C$12:C$14,MATCH($E14,'Stats base'!$A$12:$A$14,0))*INDEX('Stats base'!C$18:C$22,MATCH($J14,'Stats base'!$A$18:$A$22,0))*IFERROR(INDEX(Variación!D$3:D$228,MATCH($G14,Variación!$A$3:$A$228,0)),1),1) -> 14 | M14: =ROUND(INDEX('Stats base'!D$5:D$8,MATCH($C14,'Stats base'!$A$5:$A$8,0))*INDEX('Stats base'!D$12:D$14,MATCH($E14,'Stats base'!$A$12:$A$14,0))*INDEX('Stats base'!D$18:D$22,MATCH($J14,'Stats base'!$A$18:$A$22,0))*IFERROR(INDEX(Variación!E$3:E$228,MATCH($G14,Variación!$A$3:$A$228,0)),1),1) -> 24.5 | N14: =ROUND(INDEX('Stats base'!E$5:E$8,MATCH($C14,'Stats base'!$A$5:$A$8,0))*INDEX('Stats base'!E$12:E$14,MATCH($E14,'Stats base'!$A$12:$A$14,0))*INDEX('Stats base'!E$18:E$22,MATCH($J14,'Stats base'!$A$18:$A$22,0))*IFERROR(INDEX(Variación!F$3:F$228,MATCH($G14,Variación!$A$3:$A$228,0)),1),1) -> 3.1 | O14: =ROUND(INDEX('Stats base'!F$5:F$8,MATCH($C14,'Stats base'!$A$5:$A$8,0))*INDEX('Stats base'!F$12:F$14,MATCH($E14,'Stats base'!$A$12:$A$14,0))*INDEX('Stats base'!F$18:F$22,MATCH($J14,'Stats base'!$A$18:$A$22,0))*IFERROR(INDEX(Variación!G$3:G$228,MATCH($G14,Variación!$A$3:$A$228,0)),1),0) -> 120 | P14: =MIN('Stats base'!$G$30,ROUND(INDEX('Stats base'!G$5:G$8,MATCH($C14,'Stats base'!$A$5:$A$8,0))*INDEX('Stats base'!G$12:G$14,MATCH($E14,'Stats base'!$A$12:$A$14,0))*INDEX('Stats base'!G$18:G$22,MATCH($J14,'Stats base'!$A$18:$A$22,0))*IFERROR(INDEX(Variación!H$3:H$228,MATCH($G14,Variación!$A$3:$A$228,0)),1),3)) -> 0.034
... A196: Mitch Grumble | B196: Grumble | C196: MF | D196: Male | E196: Small | F196: Dragon | G196: 0xD7 | I196: Inazuma Kids FC | J196: Común | K196: =ROUND(INDEX('Stats base'!B$5:B$8,MATCH($C196,'Stats base'!$A$5:$A$8,0))*INDEX('Stats base'!B$12:B$14,MATCH($E196,'Stats base'!$A$12:$A$14,0))*INDEX('Stats base'!B$18:B$22,MATCH($J196,'Stats base'!$A$18:$A$22,0))*IFERROR(INDEX(Variación!C$3:C$228,MATCH($G196,Variación!$A$3:$A$228,0)),1),0) -> 84 | L196: =ROUND(INDEX('Stats base'!C$5:C$8,MATCH($C196,'Stats base'!$A$5:$A$8,0))*INDEX('Stats base'!C$12:C$14,MATCH($E196,'Stats base'!$A$12:$A$14,0))*INDEX('Stats base'!C$18:C$22,MATCH($J196,'Stats base'!$A$18:$A$22,0))*IFERROR(INDEX(Variación!D$3:D$228,MATCH($G196,Variación!$A$3:$A$228,0)),1),1) -> 8.6 | M196: =ROUND(INDEX('Stats base'!D$5:D$8,MATCH($C196,'Stats base'!$A$5:$A$8,0))*INDEX('Stats base'!D$12:D$14,MATCH($E196,'Stats base'!$A$12:$A$14,0))*INDEX('Stats base'!D$18:D$22,MATCH($J196,'Stats base'!$A$18:$A$22,0))*IFERROR(INDEX(Variación!E$3:E$228,MATCH($G196,Variación!$A$3:$A$228,0)),1),1) -> 15.8 | N196: =ROUND(INDEX('Stats base'!E$5:E$8,MATCH($C196,'Stats base'!$A$5:$A$8,0))*INDEX('Stats base'!E$12:E$14,MATCH($E196,'Stats base'!$A$12:$A$14,0))*INDEX('Stats base'!E$18:E$22,MATCH($J196,'Stats base'!$A$18:$A$22,0))*IFERROR(INDEX(Variación!F$3:F$228,MATCH($G196,Variación!$A$3:$A$228,0)),1),1) -> 3.7 | O196: =ROUND(INDEX('Stats base'!F$5:F$8,MATCH($C196,'Stats base'!$A$5:$A$8,0))*INDEX('Stats base'!F$12:F$14,MATCH($E196,'Stats base'!$A$12:$A$14,0))*INDEX('Stats base'!F$18:F$22,MATCH($J196,'Stats base'!$A$18:$A$22,0))*IFERROR(INDEX(Variación!G$3:G$228,MATCH($G196,Variación!$A$3:$A$228,0)),1),0) -> 115 | P196: =MIN('Stats base'!$G$30,ROUND(INDEX('Stats base'!G$5:G$8,MATCH($C196,'Stats base'!$A$5:$A$8,0))*INDEX('Stats base'!G$12:G$14,MATCH($E196,'Stats base'!$A$12:$A$14,0))*INDEX('Stats base'!G$18:G$22,MATCH($J196,'Stats base'!$A$18:$A$22,0))*IFERROR(INDEX(Variación!H$3:H$228,MATCH($G196,Variación!$A$3:$A$228,0)),1),3)) -> 0.039
A197: Bart Grantham | B197: Grantham | C197: GK | D197: Male | E197: Large | G197: 0xD8 | I197: Inazuma Kids FC | J197: Común | K197: =ROUND(INDEX('Stats base'!B$5:B$8,MATCH($C197,'Stats base'!$A$5:$A$8,0))*INDEX('Stats base'!B$12:B$14,MATCH($E197,'Stats base'!$A$12:$A$14,0))*INDEX('Stats base'!B$18:B$22,MATCH($J197,'Stats base'!$A$18:$A$22,0))*IFERROR(INDEX(Variación!C$3:C$228,MATCH($G197,Variación!$A$3:$A$228,0)),1),0) -> 133 | L197: =ROUND(INDEX('Stats base'!C$5:C$8,MATCH($C197,'Stats base'!$A$5:$A$8,0))*INDEX('Stats base'!C$12:C$14,MATCH($E197,'Stats base'!$A$12:$A$14,0))*INDEX('Stats base'!C$18:C$22,MATCH($J197,'Stats base'!$A$18:$A$22,0))*IFERROR(INDEX(Variación!D$3:D$228,MATCH($G197,Variación!$A$3:$A$228,0)),1),1) -> 8.7 | M197: =ROUND(INDEX('Stats base'!D$5:D$8,MATCH($C197,'Stats base'!$A$5:$A$8,0))*INDEX('Stats base'!D$12:D$14,MATCH($E197,'Stats base'!$A$12:$A$14,0))*INDEX('Stats base'!D$18:D$22,MATCH($J197,'Stats base'!$A$18:$A$22,0))*IFERROR(INDEX(Variación!E$3:E$228,MATCH($G197,Variación!$A$3:$A$228,0)),1),1) -> 19.1 | N197: =ROUND(INDEX('Stats base'!E$5:E$8,MATCH($C197,'Stats base'!$A$5:$A$8,0))*INDEX('Stats base'!E$12:E$14,MATCH($E197,'Stats base'!$A$12:$A$14,0))*INDEX('Stats base'!E$18:E$22,MATCH($J197,'Stats base'!$A$18:$A$22,0))*IFERROR(INDEX(Variación!F$3:F$228,MATCH($G197,Variación!$A$3:$A$228,0)),1),1) -> 8.1 | O197: =ROUND(INDEX('Stats base'!F$5:F$8,MATCH($C197,'Stats base'!$A$5:$A$8,0))*INDEX('Stats base'!F$12:F$14,MATCH($E197,'Stats base'!$A$12:$A$14,0))*INDEX('Stats base'!F$18:F$22,MATCH($J197,'Stats base'!$A$18:$A$22,0))*IFERROR(INDEX(Variación!G$3:G$228,MATCH($G197,Variación!$A$3:$A$228,0)),1),0) -> 72 | P197: =MIN('Stats base'!$G$30,ROUND(INDEX('Stats base'!G$5:G$8,MATCH($C197,'Stats base'!$A$5:$A$8,0))*INDEX('Stats base'!G$12:G$14,MATCH($E197,'Stats base'!$A$12:$A$14,0))*INDEX('Stats base'!G$18:G$22,MATCH($J197,'Stats base'!$A$18:$A$22,0))*IFERROR(INDEX(Variación!H$3:H$228,MATCH($G197,Variación!$A$3:$A$228,0)),1),3)) -> 0.007
A198: Joe Ingram | B198: Ingram | C198: GK | D198: Male | E198: Medium | F198: Fire | G198: 0xDD | I198: Umbrella | J198: Raro | K198: =ROUND(INDEX('Stats base'!B$5:B$8,MATCH($C198,'Stats base'!$A$5:$A$8,0))*INDEX('Stats base'!B$12:B$14,MATCH($E198,'Stats base'!$A$12:$A$14,0))*INDEX('Stats base'!B$18:B$22,MATCH($J198,'Stats base'!$A$18:$A$22,0))*IFERROR(INDEX(Variación!C$3:C$228,MATCH($G198,Variación!$A$3:$A$228,0)),1),0) -> 136 | L198: =ROUND(INDEX('Stats base'!C$5:C$8,MATCH($C198,'Stats base'!$A$5:$A$8,0))*INDEX('Stats base'!C$12:C$14,MATCH($E198,'Stats base'!$A$12:$A$14,0))*INDEX('Stats base'!C$18:C$22,MATCH($J198,'Stats base'!$A$18:$A$22,0))*IFERROR(INDEX(Variación!D$3:D$228,MATCH($G198,Variación!$A$3:$A$228,0)),1),1) -> 9.8 | M198: =ROUND(INDEX('Stats base'!D$5:D$8,MATCH($C198,'Stats base'!$A$5:$A$8,0))*INDEX('Stats base'!D$12:D$14,MATCH($E198,'Stats base'!$A$12:$A$14,0))*INDEX('Stats base'!D$18:D$22,MATCH($J198,'Stats base'!$A$18:$A$22,0))*IFERROR(INDEX(Variación!E$3:E$228,MATCH($G198,Variación!$A$3:$A$228,0)),1),1) -> 21.6 | N198: =ROUND(INDEX('Stats base'!E$5:E$8,MATCH($C198,'Stats base'!$A$5:$A$8,0))*INDEX('Stats base'!E$12:E$14,MATCH($E198,'Stats base'!$A$12:$A$14,0))*INDEX('Stats base'!E$18:E$22,MATCH($J198,'Stats base'!$A$18:$A$22,0))*IFERROR(INDEX(Variación!F$3:F$228,MATCH($G198,Variación!$A$3:$A$228,0)),1),1) -> 8 | O198: =ROUND(INDEX('Stats base'!F$5:F$8,MATCH($C198,'Stats base'!$A$5:$A$8,0))*INDEX('Stats base'!F$12:F$14,MATCH($E198,'Stats base'!$A$12:$A$14,0))*INDEX('Stats base'!F$18:F$22,MATCH($J198,'Stats base'!$A$18:$A$22,0))*IFERROR(INDEX(Variación!G$3:G$228,MATCH($G198,Variación!$A$3:$A$228,0)),1),0) -> 92 | P198: =MIN('Stats base'!$G$30,ROUND(INDEX('Stats base'!G$5:G$8,MATCH($C198,'Stats base'!$A$5:$A$8,0))*INDEX('Stats base'!G$12:G$14,MATCH($E198,'Stats base'!$A$12:$A$14,0))*INDEX('Stats base'!G$18:G$22,MATCH($J198,'Stats base'!$A$18:$A$22,0))*IFERROR(INDEX(Variación!H$3:H$228,MATCH($G198,Variación!$A$3:$A$228,0)),1),3)) -> 0.012
A199: Kendall Sefton | B199: Sefton | C199: DF | D199: Male | E199: Medium | F199: Air | G199: 0xDE | I199: Umbrella | J199: Común | K199: =ROUND(INDEX('Stats base'!B$5:B$8,MATCH($C199,'Stats base'!$A$5:$A$8,0))*INDEX('Stats base'!B$12:B$14,MATCH($E199,'Stats base'!$A$12:$A$14,0))*INDEX('Stats base'!B$18:B$22,MATCH($J199,'Stats base'!$A$18:$A$22,0))*IFERROR(INDEX(Variación!C$3:C$228,MATCH($G199,Variación!$A$3:$A$228,0)),1),0) -> 133 | L199: =ROUND(INDEX('Stats base'!C$5:C$8,MATCH($C199,'Stats base'!$A$5:$A$8,0))*INDEX('Stats base'!C$12:C$14,MATCH($E199,'Stats base'!$A$12:$A$14,0))*INDEX('Stats base'!C$18:C$22,MATCH($J199,'Stats base'!$A$18:$A$22,0))*IFERROR(INDEX(Variación!D$3:D$228,MATCH($G199,Variación!$A$3:$A$228,0)),1),1) -> 7.6 | M199: =ROUND(INDEX('Stats base'!D$5:D$8,MATCH($C199,'Stats base'!$A$5:$A$8,0))*INDEX('Stats base'!D$12:D$14,MATCH($E199,'Stats base'!$A$12:$A$14,0))*INDEX('Stats base'!D$18:D$22,MATCH($J199,'Stats base'!$A$18:$A$22,0))*IFERROR(INDEX(Variación!E$3:E$228,MATCH($G199,Variación!$A$3:$A$228,0)),1),1) -> 12.4 | N199: =ROUND(INDEX('Stats base'!E$5:E$8,MATCH($C199,'Stats base'!$A$5:$A$8,0))*INDEX('Stats base'!E$12:E$14,MATCH($E199,'Stats base'!$A$12:$A$14,0))*INDEX('Stats base'!E$18:E$22,MATCH($J199,'Stats base'!$A$18:$A$22,0))*IFERROR(INDEX(Variación!F$3:F$228,MATCH($G199,Variación!$A$3:$A$228,0)),1),1) -> 8.5 | O199: =ROUND(INDEX('Stats base'!F$5:F$8,MATCH($C199,'Stats base'!$A$5:$A$8,0))*INDEX('Stats base'!F$12:F$14,MATCH($E199,'Stats base'!$A$12:$A$14,0))*INDEX('Stats base'!F$18:F$22,MATCH($J199,'Stats base'!$A$18:$A$22,0))*IFERROR(INDEX(Variación!G$3:G$228,MATCH($G199,Variación!$A$3:$A$228,0)),1),0) -> 88 | P199: =MIN('Stats base'!$G$30,ROUND(INDEX('Stats base'!G$5:G$8,MATCH($C199,'Stats base'!$A$5:$A$8,0))*INDEX('Stats base'!G$12:G$14,MATCH($E199,'Stats base'!$A$12:$A$14,0))*INDEX('Stats base'!G$18:G$22,MATCH($J199,'Stats base'!$A$18:$A$22,0))*IFERROR(INDEX(Variación!H$3:H$228,MATCH($G199,Variación!$A$3:$A$228,0)),1),3)) -> 0.011
A200: Jason Strike | B200: Strike | C200: DF | D200: Male | E200: Medium | F200: Fire | G200: 0xDF | I200: Umbrella | J200: Común | K200: =ROUND(INDEX('Stats base'!B$5:B$8,MATCH($C200,'Stats base'!$A$5:$A$8,0))*INDEX('Stats base'!B$12:B$14,MATCH($E200,'Stats base'!$A$12:$A$14,0))*INDEX('Stats base'!B$18:B$22,MATCH($J200,'Stats base'!$A$18:$A$22,0))*IFERROR(INDEX(Variación!C$3:C$228,MATCH($G200,Variación!$A$3:$A$228,0)),1),0) -> 126 | L200: =ROUND(INDEX('Stats base'!C$5:C$8,MATCH($C200,'Stats base'!$A$5:$A$8,0))*INDEX('Stats base'!C$12:C$14,MATCH($E200,'Stats base'!$A$12:$A$14,0))*INDEX('Stats base'!C$18:C$22,MATCH($J200,'Stats base'!$A$18:$A$22,0))*IFERROR(INDEX(Variación!D$3:D$228,MATCH($G200,Variación!$A$3:$A$228,0)),1),1) -> 6.7 | M200: =ROUND(INDEX('Stats base'!D$5:D$8,MATCH($C200,'Stats base'!$A$5:$A$8,0))*INDEX('Stats base'!D$12:D$14,MATCH($E200,'Stats base'!$A$12:$A$14,0))*INDEX('Stats base'!D$18:D$22,MATCH($J200,'Stats base'!$A$18:$A$22,0))*IFERROR(INDEX(Variación!E$3:E$228,MATCH($G200,Variación!$A$3:$A$228,0)),1),1) -> 12.1 | N200: =ROUND(INDEX('Stats base'!E$5:E$8,MATCH($C200,'Stats base'!$A$5:$A$8,0))*INDEX('Stats base'!E$12:E$14,MATCH($E200,'Stats base'!$A$12:$A$14,0))*INDEX('Stats base'!E$18:E$22,MATCH($J200,'Stats base'!$A$18:$A$22,0))*IFERROR(INDEX(Variación!F$3:F$228,MATCH($G200,Variación!$A$3:$A$228,0)),1),1) -> 8.2 | O200: =ROUND(INDEX('Stats base'!F$5:F$8,MATCH($C200,'Stats base'!$A$5:$A$8,0))*INDEX('Stats base'!F$12:F$14,MATCH($E200,'Stats base'!$A$12:$A$14,0))*INDEX('Stats base'!F$18:F$22,MATCH($J200,'Stats base'!$A$18:$A$22,0))*IFERROR(INDEX(Variación!G$3:G$228,MATCH($G200,Variación!$A$3:$A$228,0)),1),0) -> 96 | P200: =MIN('Stats base'!$G$30,ROUND(INDEX('Stats base'!G$5:G$8,MATCH($C200,'Stats base'!$A$5:$A$8,0))*INDEX('Stats base'!G$12:G$14,MATCH($E200,'Stats base'!$A$12:$A$14,0))*INDEX('Stats base'!G$18:G$22,MATCH($J200,'Stats base'!$A$18:$A$22,0))*IFERROR(INDEX(Variación!H$3:H$228,MATCH($G200,Variación!$A$3:$A$228,0)),1),3)) -> 0.013
A201: Norman Porter | B201: Porter | C201: DF | D201: Male | E201: Large | F201: Earth | G201: 0xE0 | I201: Umbrella | J201: Común | K201: =ROUND(INDEX('Stats base'!B$5:B$8,MATCH($C201,'Stats base'!$A$5:$A$8,0))*INDEX('Stats base'!B$12:B$14,MATCH($E201,'Stats base'!$A$12:$A$14,0))*INDEX('Stats base'!B$18:B$22,MATCH($J201,'Stats base'!$A$18:$A$22,0))*IFERROR(INDEX(Variación!C$3:C$228,MATCH($G201,Variación!$A$3:$A$228,0)),1),0) -> 147 | L201: =ROUND(INDEX('Stats base'!C$5:C$8,MATCH($C201,'Stats base'!$A$5:$A$8,0))*INDEX('Stats base'!C$12:C$14,MATCH($E201,'Stats base'!$A$12:$A$14,0))*INDEX('Stats base'!C$18:C$22,MATCH($J201,'Stats base'!$A$18:$A$22,0))*IFERROR(INDEX(Variación!D$3:D$228,MATCH($G201,Variación!$A$3:$A$228,0)),1),1) -> 8.2 | M201: =ROUND(INDEX('Stats base'!D$5:D$8,MATCH($C201,'Stats base'!$A$5:$A$8,0))*INDEX('Stats base'!D$12:D$14,MATCH($E201,'Stats base'!$A$12:$A$14,0))*INDEX('Stats base'!D$18:D$22,MATCH($J201,'Stats base'!$A$18:$A$22,0))*IFERROR(INDEX(Variación!E$3:E$228,MATCH($G201,Variación!$A$3:$A$228,0)),1),1) -> 13.9 | N201: =ROUND(INDEX('Stats base'!E$5:E$8,MATCH($C201,'Stats base'!$A$5:$A$8,0))*INDEX('Stats base'!E$12:E$14,MATCH($E201,'Stats base'!$A$12:$A$14,0))*INDEX('Stats base'!E$18:E$22,MATCH($J201,'Stats base'!$A$18:$A$22,0))*IFERROR(INDEX(Variación!F$3:F$228,MATCH($G201,Variación!$A$3:$A$228,0)),1),1) -> 9.9 | O201: =ROUND(INDEX('Stats base'!F$5:F$8,MATCH($C201,'Stats base'!$A$5:$A$8,0))*INDEX('Stats base'!F$12:F$14,MATCH($E201,'Stats base'!$A$12:$A$14,0))*INDEX('Stats base'!F$18:F$22,MATCH($J201,'Stats base'!$A$18:$A$22,0))*IFERROR(INDEX(Variación!G$3:G$228,MATCH($G201,Variación!$A$3:$A$228,0)),1),0) -> 74 | P201: =MIN('Stats base'!$G$30,ROUND(INDEX('Stats base'!G$5:G$8,MATCH($C201,'Stats base'!$A$5:$A$8,0))*INDEX('Stats base'!G$12:G$14,MATCH($E201,'Stats base'!$A$12:$A$14,0))*INDEX('Stats base'!G$18:G$22,MATCH($J201,'Stats base'!$A$18:$A$22,0))*IFERROR(INDEX(Variación!H$3:H$228,MATCH($G201,Variación!$A$3:$A$228,0)),1),3)) -> 0.009
A202: Maxwell Claus | B202: Chops | C202: DF | D202: Male | E202: Medium | F202: Wood | G202: 0xE1 | I202: Umbrella | J202: Común | K202: =ROUND(INDEX('Stats base'!B$5:B$8,MATCH($C202,'Stats base'!$A$5:$A$8,0))*INDEX('Stats base'!B$12:B$14,MATCH($E202,'Stats base'!$A$12:$A$14,0))*INDEX('Stats base'!B$18:B$22,MATCH($J202,'Stats base'!$A$18:$A$22,0))*IFERROR(INDEX(Variación!C$3:C$228,MATCH($G202,Variación!$A$3:$A$228,0)),1),0) -> 118 | L202: =ROUND(INDEX('Stats base'!C$5:C$8,MATCH($C202,'Stats base'!$A$5:$A$8,0))*INDEX('Stats base'!C$12:C$14,MATCH($E202,'Stats base'!$A$12:$A$14,0))*INDEX('Stats base'!C$18:C$22,MATCH($J202,'Stats base'!$A$18:$A$22,0))*IFERROR(INDEX(Variación!D$3:D$228,MATCH($G202,Variación!$A$3:$A$228,0)),1),1) -> 7.2 | M202: =ROUND(INDEX('Stats base'!D$5:D$8,MATCH($C202,'Stats base'!$A$5:$A$8,0))*INDEX('Stats base'!D$12:D$14,MATCH($E202,'Stats base'!$A$12:$A$14,0))*INDEX('Stats base'!D$18:D$22,MATCH($J202,'Stats base'!$A$18:$A$22,0))*IFERROR(INDEX(Variación!E$3:E$228,MATCH($G202,Variación!$A$3:$A$228,0)),1),1) -> 12.4 | N202: =ROUND(INDEX('Stats base'!E$5:E$8,MATCH($C202,'Stats base'!$A$5:$A$8,0))*INDEX('Stats base'!E$12:E$14,MATCH($E202,'Stats base'!$A$12:$A$14,0))*INDEX('Stats base'!E$18:E$22,MATCH($J202,'Stats base'!$A$18:$A$22,0))*IFERROR(INDEX(Variación!F$3:F$228,MATCH($G202,Variación!$A$3:$A$228,0)),1),1) -> 7.9 | O202: =ROUND(INDEX('Stats base'!F$5:F$8,MATCH($C202,'Stats base'!$A$5:$A$8,0))*INDEX('Stats base'!F$12:F$14,MATCH($E202,'Stats base'!$A$12:$A$14,0))*INDEX('Stats base'!F$18:F$22,MATCH($J202,'Stats base'!$A$18:$A$22,0))*IFERROR(INDEX(Variación!G$3:G$228,MATCH($G202,Variación!$A$3:$A$228,0)),1),0) -> 90 | P202: =MIN('Stats base'!$G$30,ROUND(INDEX('Stats base'!G$5:G$8,MATCH($C202,'Stats base'!$A$5:$A$8,0))*INDEX('Stats base'!G$12:G$14,MATCH($E202,'Stats base'!$A$12:$A$14,0))*INDEX('Stats base'!G$18:G$22,MATCH($J202,'Stats base'!$A$18:$A$22,0))*IFERROR(INDEX(Variación!H$3:H$228,MATCH($G202,Variación!$A$3:$A$228,0)),1),3)) -> 0.012
A203: Bruce Chaney | B203: Chaney | C203: MF | D203: Male | E203: Medium | F203: Wood | G203: 0xE2 | I203: Umbrella | J203: Común | K203: =ROUND(INDEX('Stats base'!B$5:B$8,MATCH($C203,'Stats base'!$A$5:$A$8,0))*INDEX('Stats base'!B$12:B$14,MATCH($E203,'Stats base'!$A$12:$A$14,0))*INDEX('Stats base'!B$18:B$22,MATCH($J203,'Stats base'!$A$18:$A$22,0))*IFERROR(INDEX(Variación!C$3:C$228,MATCH($G203,Variación!$A$3:$A$228,0)),1),0) -> 95 | L203: =ROUND(INDEX('Stats base'!C$5:C$8,MATCH($C203,'Stats base'!$A$5:$A$8,0))*INDEX('Stats base'!C$12:C$14,MATCH($E203,'Stats base'!$A$12:$A$14,0))*INDEX('Stats base'!C$18:C$22,MATCH($J203,'Stats base'!$A$18:$A$22,0))*IFERROR(INDEX(Variación!D$3:D$228,MATCH($G203,Variación!$A$3:$A$228,0)),1),1) -> 9.3 | M203: =ROUND(INDEX('Stats base'!D$5:D$8,MATCH($C203,'Stats base'!$A$5:$A$8,0))*INDEX('Stats base'!D$12:D$14,MATCH($E203,'Stats base'!$A$12:$A$14,0))*INDEX('Stats base'!D$18:D$22,MATCH($J203,'Stats base'!$A$18:$A$22,0))*IFERROR(INDEX(Variación!E$3:E$228,MATCH($G203,Variación!$A$3:$A$228,0)),1),1) -> 14.9 | N203: =ROUND(INDEX('Stats base'!E$5:E$8,MATCH($C203,'Stats base'!$A$5:$A$8,0))*INDEX('Stats base'!E$12:E$14,MATCH($E203,'Stats base'!$A$12:$A$14,0))*INDEX('Stats base'!E$18:E$22,MATCH($J203,'Stats base'!$A$18:$A$22,0))*IFERROR(INDEX(Variación!F$3:F$228,MATCH($G203,Variación!$A$3:$A$228,0)),1),1) -> 4 | O203: =ROUND(INDEX('Stats base'!F$5:F$8,MATCH($C203,'Stats base'!$A$5:$A$8,0))*INDEX('Stats base'!F$12:F$14,MATCH($E203,'Stats base'!$A$12:$A$14,0))*INDEX('Stats base'!F$18:F$22,MATCH($J203,'Stats base'!$A$18:$A$22,0))*IFERROR(INDEX(Variación!G$3:G$228,MATCH($G203,Variación!$A$3:$A$228,0)),1),0) -> 107 | P203: =MIN('Stats base'!$G$30,ROUND(INDEX('Stats base'!G$5:G$8,MATCH($C203,'Stats base'!$A$5:$A$8,0))*INDEX('Stats base'!G$12:G$14,MATCH($E203,'Stats base'!$A$12:$A$14,0))*INDEX('Stats base'!G$18:G$22,MATCH($J203,'Stats base'!$A$18:$A$22,0))*IFERROR(INDEX(Variación!H$3:H$228,MATCH($G203,Variación!$A$3:$A$228,0)),1),3)) -> 0.035
A204: Leroy Rhymes | B204: Rhymes | C204: MF | D204: Male | E204: Small | F204: Air | G204: 0xE3 | I204: Umbrella | J204: Común | K204: =ROUND(INDEX('Stats base'!B$5:B$8,MATCH($C204,'Stats base'!$A$5:$A$8,0))*INDEX('Stats base'!B$12:B$14,MATCH($E204,'Stats base'!$A$12:$A$14,0))*INDEX('Stats base'!B$18:B$22,MATCH($J204,'Stats base'!$A$18:$A$22,0))*IFERROR(INDEX(Variación!C$3:C$228,MATCH($G204,Variación!$A$3:$A$228,0)),1),0) -> 91 | L204: =ROUND(INDEX('Stats base'!C$5:C$8,MATCH($C204,'Stats base'!$A$5:$A$8,0))*INDEX('Stats base'!C$12:C$14,MATCH($E204,'Stats base'!$A$12:$A$14,0))*INDEX('Stats base'!C$18:C$22,MATCH($J204,'Stats base'!$A$18:$A$22,0))*IFERROR(INDEX(Variación!D$3:D$228,MATCH($G204,Variación!$A$3:$A$228,0)),1),1) -> 9.4 | M204: =ROUND(INDEX('Stats base'!D$5:D$8,MATCH($C204,'Stats base'!$A$5:$A$8,0))*INDEX('Stats base'!D$12:D$14,MATCH($E204,'Stats base'!$A$12:$A$14,0))*INDEX('Stats base'!D$18:D$22,MATCH($J204,'Stats base'!$A$18:$A$22,0))*IFERROR(INDEX(Variación!E$3:E$228,MATCH($G204,Variación!$A$3:$A$228,0)),1),1) -> 16.3 | N204: =ROUND(INDEX('Stats base'!E$5:E$8,MATCH($C204,'Stats base'!$A$5:$A$8,0))*INDEX('Stats base'!E$12:E$14,MATCH($E204,'Stats base'!$A$12:$A$14,0))*INDEX('Stats base'!E$18:E$22,MATCH($J204,'Stats base'!$A$18:$A$22,0))*IFERROR(INDEX(Variación!F$3:F$228,MATCH($G204,Variación!$A$3:$A$228,0)),1),1) -> 3.9 | O204: =ROUND(INDEX('Stats base'!F$5:F$8,MATCH($C204,'Stats base'!$A$5:$A$8,0))*INDEX('Stats base'!F$12:F$14,MATCH($E204,'Stats base'!$A$12:$A$14,0))*INDEX('Stats base'!F$18:F$22,MATCH($J204,'Stats base'!$A$18:$A$22,0))*IFERROR(INDEX(Variación!G$3:G$228,MATCH($G204,Variación!$A$3:$A$228,0)),1),0) -> 113 | P204: =MIN('Stats base'!$G$30,ROUND(INDEX('Stats base'!G$5:G$8,MATCH($C204,'Stats base'!$A$5:$A$8,0))*INDEX('Stats base'!G$12:G$14,MATCH($E204,'Stats base'!$A$12:$A$14,0))*INDEX('Stats base'!G$18:G$22,MATCH($J204,'Stats base'!$A$18:$A$22,0))*IFERROR(INDEX(Variación!H$3:H$228,MATCH($G204,Variación!$A$3:$A$228,0)),1),3)) -> 0.038
A205: Mildford Scott | B205: Scott | C205: MF | D205: Male | E205: Medium | F205: Wood | G205: 0xE4 | I205: Umbrella | J205: Común | K205: =ROUND(INDEX('Stats base'!B$5:B$8,MATCH($C205,'Stats base'!$A$5:$A$8,0))*INDEX('Stats base'!B$12:B$14,MATCH($E205,'Stats base'!$A$12:$A$14,0))*INDEX('Stats base'!B$18:B$22,MATCH($J205,'Stats base'!$A$18:$A$22,0))*IFERROR(INDEX(Variación!C$3:C$228,MATCH($G205,Variación!$A$3:$A$228,0)),1),0) -> 100 | L205: =ROUND(INDEX('Stats base'!C$5:C$8,MATCH($C205,'Stats base'!$A$5:$A$8,0))*INDEX('Stats base'!C$12:C$14,MATCH($E205,'Stats base'!$A$12:$A$14,0))*INDEX('Stats base'!C$18:C$22,MATCH($J205,'Stats base'!$A$18:$A$22,0))*IFERROR(INDEX(Variación!D$3:D$228,MATCH($G205,Variación!$A$3:$A$228,0)),1),1) -> 8.6 | M205: =ROUND(INDEX('Stats base'!D$5:D$8,MATCH($C205,'Stats base'!$A$5:$A$8,0))*INDEX('Stats base'!D$12:D$14,MATCH($E205,'Stats base'!$A$12:$A$14,0))*INDEX('Stats base'!D$18:D$22,MATCH($J205,'Stats base'!$A$18:$A$22,0))*IFERROR(INDEX(Variación!E$3:E$228,MATCH($G205,Variación!$A$3:$A$228,0)),1),1) -> 15.7 | N205: =ROUND(INDEX('Stats base'!E$5:E$8,MATCH($C205,'Stats base'!$A$5:$A$8,0))*INDEX('Stats base'!E$12:E$14,MATCH($E205,'Stats base'!$A$12:$A$14,0))*INDEX('Stats base'!E$18:E$22,MATCH($J205,'Stats base'!$A$18:$A$22,0))*IFERROR(INDEX(Variación!F$3:F$228,MATCH($G205,Variación!$A$3:$A$228,0)),1),1) -> 4.3 | O205: =ROUND(INDEX('Stats base'!F$5:F$8,MATCH($C205,'Stats base'!$A$5:$A$8,0))*INDEX('Stats base'!F$12:F$14,MATCH($E205,'Stats base'!$A$12:$A$14,0))*INDEX('Stats base'!F$18:F$22,MATCH($J205,'Stats base'!$A$18:$A$22,0))*IFERROR(INDEX(Variación!G$3:G$228,MATCH($G205,Variación!$A$3:$A$228,0)),1),0) -> 111 | P205: =MIN('Stats base'!$G$30,ROUND(INDEX('Stats base'!G$5:G$8,MATCH($C205,'Stats base'!$A$5:$A$8,0))*INDEX('Stats base'!G$12:G$14,MATCH($E205,'Stats base'!$A$12:$A$14,0))*INDEX('Stats base'!G$18:G$22,MATCH($J205,'Stats base'!$A$18:$A$22,0))*IFERROR(INDEX(Variación!H$3:H$228,MATCH($G205,Variación!$A$3:$A$228,0)),1),3)) -> 0.036
A206: Lou Edmonds | B206: Edmonds | C206: FW | D206: Male | E206: Medium | F206: Fire | G206: 0xE5 | I206: Umbrella | J206: Raro | K206: =ROUND(INDEX('Stats base'!B$5:B$8,MATCH($C206,'Stats base'!$A$5:$A$8,0))*INDEX('Stats base'!B$12:B$14,MATCH($E206,'Stats base'!$A$12:$A$14,0))*INDEX('Stats base'!B$18:B$22,MATCH($J206,'Stats base'!$A$18:$A$22,0))*IFERROR(INDEX(Variación!C$3:C$228,MATCH($G206,Variación!$A$3:$A$228,0)),1),0) -> 97 | L206: =ROUND(INDEX('Stats base'!C$5:C$8,MATCH($C206,'Stats base'!$A$5:$A$8,0))*INDEX('Stats base'!C$12:C$14,MATCH($E206,'Stats base'!$A$12:$A$14,0))*INDEX('Stats base'!C$18:C$22,MATCH($J206,'Stats base'!$A$18:$A$22,0))*IFERROR(INDEX(Variación!D$3:D$228,MATCH($G206,Variación!$A$3:$A$228,0)),1),1) -> 12.9 | M206: =ROUND(INDEX('Stats base'!D$5:D$8,MATCH($C206,'Stats base'!$A$5:$A$8,0))*INDEX('Stats base'!D$12:D$14,MATCH($E206,'Stats base'!$A$12:$A$14,0))*INDEX('Stats base'!D$18:D$22,MATCH($J206,'Stats base'!$A$18:$A$22,0))*IFERROR(INDEX(Variación!E$3:E$228,MATCH($G206,Variación!$A$3:$A$228,0)),1),1) -> 23 | N206: =ROUND(INDEX('Stats base'!E$5:E$8,MATCH($C206,'Stats base'!$A$5:$A$8,0))*INDEX('Stats base'!E$12:E$14,MATCH($E206,'Stats base'!$A$12:$A$14,0))*INDEX('Stats base'!E$18:E$22,MATCH($J206,'Stats base'!$A$18:$A$22,0))*IFERROR(INDEX(Variación!F$3:F$228,MATCH($G206,Variación!$A$3:$A$228,0)),1),1) -> 3.4 | O206: =ROUND(INDEX('Stats base'!F$5:F$8,MATCH($C206,'Stats base'!$A$5:$A$8,0))*INDEX('Stats base'!F$12:F$14,MATCH($E206,'Stats base'!$A$12:$A$14,0))*INDEX('Stats base'!F$18:F$22,MATCH($J206,'Stats base'!$A$18:$A$22,0))*IFERROR(INDEX(Variación!G$3:G$228,MATCH($G206,Variación!$A$3:$A$228,0)),1),0) -> 120 | P206: =MIN('Stats base'!$G$30,ROUND(INDEX('Stats base'!G$5:G$8,MATCH($C206,'Stats base'!$A$5:$A$8,0))*INDEX('Stats base'!G$12:G$14,MATCH($E206,'Stats base'!$A$12:$A$14,0))*INDEX('Stats base'!G$18:G$22,MATCH($J206,'Stats base'!$A$18:$A$22,0))*IFERROR(INDEX(Variación!H$3:H$228,MATCH($G206,Variación!$A$3:$A$228,0)),1),3)) -> 0.034
A207: Cameron Morefield | B207: Morefield | C207: MF | D207: Male | E207: Medium | F207: Air | G207: 0xE6 | I207: Umbrella | J207: Raro | K207: =ROUND(INDEX('Stats base'!B$5:B$8,MATCH($C207,'Stats base'!$A$5:$A$8,0))*INDEX('Stats base'!B$12:B$14,MATCH($E207,'Stats base'!$A$12:$A$14,0))*INDEX('Stats base'!B$18:B$22,MATCH($J207,'Stats base'!$A$18:$A$22,0))*IFERROR(INDEX(Variación!C$3:C$228,MATCH($G207,Variación!$A$3:$A$228,0)),1),0) -> 101 | L207: =ROUND(INDEX('Stats base'!C$5:C$8,MATCH($C207,'Stats base'!$A$5:$A$8,0))*INDEX('Stats base'!C$12:C$14,MATCH($E207,'Stats base'!$A$12:$A$14,0))*INDEX('Stats base'!C$18:C$22,MATCH($J207,'Stats base'!$A$18:$A$22,0))*IFERROR(INDEX(Variación!D$3:D$228,MATCH($G207,Variación!$A$3:$A$228,0)),1),1) -> 11.9 | M207: =ROUND(INDEX('Stats base'!D$5:D$8,MATCH($C207,'Stats base'!$A$5:$A$8,0))*INDEX('Stats base'!D$12:D$14,MATCH($E207,'Stats base'!$A$12:$A$14,0))*INDEX('Stats base'!D$18:D$22,MATCH($J207,'Stats base'!$A$18:$A$22,0))*IFERROR(INDEX(Variación!E$3:E$228,MATCH($G207,Variación!$A$3:$A$228,0)),1),1) -> 20.2 | N207: =ROUND(INDEX('Stats base'!E$5:E$8,MATCH($C207,'Stats base'!$A$5:$A$8,0))*INDEX('Stats base'!E$12:E$14,MATCH($E207,'Stats base'!$A$12:$A$14,0))*INDEX('Stats base'!E$18:E$22,MATCH($J207,'Stats base'!$A$18:$A$22,0))*IFERROR(INDEX(Variación!F$3:F$228,MATCH($G207,Variación!$A$3:$A$228,0)),1),1) -> 4.6 | O207: =ROUND(INDEX('Stats base'!F$5:F$8,MATCH($C207,'Stats base'!$A$5:$A$8,0))*INDEX('Stats base'!F$12:F$14,MATCH($E207,'Stats base'!$A$12:$A$14,0))*INDEX('Stats base'!F$18:F$22,MATCH($J207,'Stats base'!$A$18:$A$22,0))*IFERROR(INDEX(Variación!G$3:G$228,MATCH($G207,Variación!$A$3:$A$228,0)),1),0) -> 109 | P207: =MIN('Stats base'!$G$30,ROUND(INDEX('Stats base'!G$5:G$8,MATCH($C207,'Stats base'!$A$5:$A$8,0))*INDEX('Stats base'!G$12:G$14,MATCH($E207,'Stats base'!$A$12:$A$14,0))*INDEX('Stats base'!G$18:G$22,MATCH($J207,'Stats base'!$A$18:$A$22,0))*IFERROR(INDEX(Variación!H$3:H$228,MATCH($G207,Variación!$A$3:$A$228,0)),1),3)) -> 0.05
A208: Greg Bernard | B208: Cyborg | C208: FW | D208: Male | E208: Medium | F208: Wood | G208: 0xE7 | I208: Umbrella | J208: Raro | K208: =ROUND(INDEX('Stats base'!B$5:B$8,MATCH($C208,'Stats base'!$A$5:$A$8,0))*INDEX('Stats base'!B$12:B$14,MATCH($E208,'Stats base'!$A$12:$A$14,0))*INDEX('Stats base'!B$18:B$22,MATCH($J208,'Stats base'!$A$18:$A$22,0))*IFERROR(INDEX(Variación!C$3:C$228,MATCH($G208,Variación!$A$3:$A$228,0)),1),0) -> 101 | L208: =ROUND(INDEX('Stats base'!C$5:C$8,MATCH($C208,'Stats base'!$A$5:$A$8,0))*INDEX('Stats base'!C$12:C$14,MATCH($E208,'Stats base'!$A$12:$A$14,0))*INDEX('Stats base'!C$18:C$22,MATCH($J208,'Stats base'!$A$18:$A$22,0))*IFERROR(INDEX(Variación!D$3:D$228,MATCH($G208,Variación!$A$3:$A$228,0)),1),1) -> 16.8 | M208: =ROUND(INDEX('Stats base'!D$5:D$8,MATCH($C208,'Stats base'!$A$5:$A$8,0))*INDEX('Stats base'!D$12:D$14,MATCH($E208,'Stats base'!$A$12:$A$14,0))*INDEX('Stats base'!D$18:D$22,MATCH($J208,'Stats base'!$A$18:$A$22,0))*IFERROR(INDEX(Variación!E$3:E$228,MATCH($G208,Variación!$A$3:$A$228,0)),1),1) -> 28.3 | N208: =ROUND(INDEX('Stats base'!E$5:E$8,MATCH($C208,'Stats base'!$A$5:$A$8,0))*INDEX('Stats base'!E$12:E$14,MATCH($E208,'Stats base'!$A$12:$A$14,0))*INDEX('Stats base'!E$18:E$22,MATCH($J208,'Stats base'!$A$18:$A$22,0))*IFERROR(INDEX(Variación!F$3:F$228,MATCH($G208,Variación!$A$3:$A$228,0)),1),1) -> 3.8 | O208: =ROUND(INDEX('Stats base'!F$5:F$8,MATCH($C208,'Stats base'!$A$5:$A$8,0))*INDEX('Stats base'!F$12:F$14,MATCH($E208,'Stats base'!$A$12:$A$14,0))*INDEX('Stats base'!F$18:F$22,MATCH($J208,'Stats base'!$A$18:$A$22,0))*IFERROR(INDEX(Variación!G$3:G$228,MATCH($G208,Variación!$A$3:$A$228,0)),1),0) -> 98 | P208: =MIN('Stats base'!$G$30,ROUND(INDEX('Stats base'!G$5:G$8,MATCH($C208,'Stats base'!$A$5:$A$8,0))*INDEX('Stats base'!G$12:G$14,MATCH($E208,'Stats base'!$A$12:$A$14,0))*INDEX('Stats base'!G$18:G$22,MATCH($J208,'Stats base'!$A$18:$A$22,0))*IFERROR(INDEX(Variación!H$3:H$228,MATCH($G208,Variación!$A$3:$A$228,0)),1),3)) -> 0.028
A209: Peter Banker | B209: Banker | C209: GK | D209: Male | E209: Medium | F209: Air | G209: 0xE8 | I209: Umbrella | J209: Común | K209: =ROUND(INDEX('Stats base'!B$5:B$8,MATCH($C209,'Stats base'!$A$5:$A$8,0))*INDEX('Stats base'!B$12:B$14,MATCH($E209,'Stats base'!$A$12:$A$14,0))*INDEX('Stats base'!B$18:B$22,MATCH($J209,'Stats base'!$A$18:$A$22,0))*IFERROR(INDEX(Variación!C$3:C$228,MATCH($G209,Variación!$A$3:$A$228,0)),1),0) -> 120 | L209: =ROUND(INDEX('Stats base'!C$5:C$8,MATCH($C209,'Stats base'!$A$5:$A$8,0))*INDEX('Stats base'!C$12:C$14,MATCH($E209,'Stats base'!$A$12:$A$14,0))*INDEX('Stats base'!C$18:C$22,MATCH($J209,'Stats base'!$A$18:$A$22,0))*IFERROR(INDEX(Variación!D$3:D$228,MATCH($G209,Variación!$A$3:$A$228,0)),1),1) -> 8.7 | M209: =ROUND(INDEX('Stats base'!D$5:D$8,MATCH($C209,'Stats base'!$A$5:$A$8,0))*INDEX('Stats base'!D$12:D$14,MATCH($E209,'Stats base'!$A$12:$A$14,0))*INDEX('Stats base'!D$18:D$22,MATCH($J209,'Stats base'!$A$18:$A$22,0))*IFERROR(INDEX(Variación!E$3:E$228,MATCH($G209,Variación!$A$3:$A$228,0)),1),1) -> 19.6 | N209: =ROUND(INDEX('Stats base'!E$5:E$8,MATCH($C209,'Stats base'!$A$5:$A$8,0))*INDEX('Stats base'!E$12:E$14,MATCH($E209,'Stats base'!$A$12:$A$14,0))*INDEX('Stats base'!E$18:E$22,MATCH($J209,'Stats base'!$A$18:$A$22,0))*IFERROR(INDEX(Variación!F$3:F$228,MATCH($G209,Variación!$A$3:$A$228,0)),1),1) -> 7.1 | O209: =ROUND(INDEX('Stats base'!F$5:F$8,MATCH($C209,'Stats base'!$A$5:$A$8,0))*INDEX('Stats base'!F$12:F$14,MATCH($E209,'Stats base'!$A$12:$A$14,0))*INDEX('Stats base'!F$18:F$22,MATCH($J209,'Stats base'!$A$18:$A$22,0))*IFERROR(INDEX(Variación!G$3:G$228,MATCH($G209,Variación!$A$3:$A$228,0)),1),0) -> 81 | P209: =MIN('Stats base'!$G$30,ROUND(INDEX('Stats base'!G$5:G$8,MATCH($C209,'Stats base'!$A$5:$A$8,0))*INDEX('Stats base'!G$12:G$14,MATCH($E209,'Stats base'!$A$12:$A$14,0))*INDEX('Stats base'!G$18:G$22,MATCH($J209,'Stats base'!$A$18:$A$22,0))*IFERROR(INDEX(Variación!H$3:H$228,MATCH($G209,Variación!$A$3:$A$228,0)),1),3)) -> 0.007
... A228: Doug Baughan | B228: Baughan | C228: FW | D228: Male | E228: Medium | F228: Air | G228: 0xFF | I228: Street Sally's | J228: Común | K228: =ROUND(INDEX('Stats base'!B$5:B$8,MATCH($C228,'Stats base'!$A$5:$A$8,0))*INDEX('Stats base'!B$12:B$14,MATCH($E228,'Stats base'!$A$12:$A$14,0))*INDEX('Stats base'!B$18:B$22,MATCH($J228,'Stats base'!$A$18:$A$22,0))*IFERROR(INDEX(Variación!C$3:C$228,MATCH($G228,Variación!$A$3:$A$228,0)),1),0) -> 82 | L228: =ROUND(INDEX('Stats base'!C$5:C$8,MATCH($C228,'Stats base'!$A$5:$A$8,0))*INDEX('Stats base'!C$12:C$14,MATCH($E228,'Stats base'!$A$12:$A$14,0))*INDEX('Stats base'!C$18:C$22,MATCH($J228,'Stats base'!$A$18:$A$22,0))*IFERROR(INDEX(Variación!D$3:D$228,MATCH($G228,Variación!$A$3:$A$228,0)),1),1) -> 12.7 | M228: =ROUND(INDEX('Stats base'!D$5:D$8,MATCH($C228,'Stats base'!$A$5:$A$8,0))*INDEX('Stats base'!D$12:D$14,MATCH($E228,'Stats base'!$A$12:$A$14,0))*INDEX('Stats base'!D$18:D$22,MATCH($J228,'Stats base'!$A$18:$A$22,0))*IFERROR(INDEX(Variación!E$3:E$228,MATCH($G228,Variación!$A$3:$A$228,0)),1),1) -> 21.2 | N228: =ROUND(INDEX('Stats base'!E$5:E$8,MATCH($C228,'Stats base'!$A$5:$A$8,0))*INDEX('Stats base'!E$12:E$14,MATCH($E228,'Stats base'!$A$12:$A$14,0))*INDEX('Stats base'!E$18:E$22,MATCH($J228,'Stats base'!$A$18:$A$22,0))*IFERROR(INDEX(Variación!F$3:F$228,MATCH($G228,Variación!$A$3:$A$228,0)),1),1) -> 3.1 | O228: =ROUND(INDEX('Stats base'!F$5:F$8,MATCH($C228,'Stats base'!$A$5:$A$8,0))*INDEX('Stats base'!F$12:F$14,MATCH($E228,'Stats base'!$A$12:$A$14,0))*INDEX('Stats base'!F$18:F$22,MATCH($J228,'Stats base'!$A$18:$A$22,0))*IFERROR(INDEX(Variación!G$3:G$228,MATCH($G228,Variación!$A$3:$A$228,0)),1),0) -> 101 | P228: =MIN('Stats base'!$G$30,ROUND(INDEX('Stats base'!G$5:G$8,MATCH($C228,'Stats base'!$A$5:$A$8,0))*INDEX('Stats base'!G$12:G$14,MATCH($E228,'Stats base'!$A$12:$A$14,0))*INDEX('Stats base'!G$18:G$22,MATCH($J228,'Stats base'!$A$18:$A$22,0))*IFERROR(INDEX(Variación!H$3:H$228,MATCH($G228,Variación!$A$3:$A$228,0)),1),3)) -> 0.019

Sheet Stats base
A3: Base por posición (jugador Común, tamaño Medium)
A4: Posición | B4: Vida | C4: Ataque | D4: Ataque especial | E4: Defensa | F4: Velocidad | G4: Regate | H4: Perfil
A5: FW | B5: 80 | C5: 12 | D5: 20 | E5: 3 | F5: 100 | G5: 0.02 | H5: Delanteros: pegan más
A6: MF | B6: 90 | C6: 9 | D6: 16 | E6: 4 | F6: 108 | G6: 0.035 | H6: Centrocampistas: más velocidad y regate
A7: DF | B7: 125 | C7: 7 | D7: 12 | E7: 8 | F7: 92 | G7: 0.012 | H7: Defensas: más vida y defensa
A8: GK | B8: 115 | C8: 8 | D8: 18 | E8: 7 | F8: 85 | G8: 0.008 | H8: Porteros: aguantan mucho, algo de pegada, lentos
A10: Multiplicador por tamaño
A11: Size | B11: Vida | C11: Ataque | D11: Ataque especial | E11: Defensa | F11: Velocidad | G11: Regate
A12: Small | B12: 0.95 | C12: 0.95 | D12: 0.95 | E12: 0.95 | F12: 1.1 | G12: 1.15
A13: Medium | B13: 1 | C13: 1 | D13: 1 | E13: 1 | F13: 1 | G13: 1
A14: Large | B14: 1.1 | C14: 1.05 | D14: 1.05 | E14: 1.1 | F14: 0.88 | G14: 0.85
A16: Multiplicador por rareza
A17: Rareza | B17: Vida | C17: Ataque | D17: Ataque especial | E17: Defensa | F17: Velocidad | G17: Regate
A18: Común | B18: 1 | C18: 1 | D18: 1 | E18: 1 | F18: 1 | G18: 1
A19: Poco Común | B19: 1.1 | C19: 1.12 | D19: 1.12 | E19: 1.1 | F19: 1.02 | G19: 1.25
A20: Raro | B20: 1.22 | C20: 1.25 | D20: 1.25 | E20: 1.22 | F20: 1.04 | G20: 1.5
A21: Épico | B21: 1.38 | C21: 1.45 | D21: 1.45 | E21: 1.4 | F21: 1.06 | G21: 1.8
A22: Legendario | B22: 1.55 | C22: 1.7 | D22: 1.7 | E22: 1.6 | F22: 1.08 | G22: 2.2
A23: Fórmula de cada stat inicial = Base de la posición × Multiplicador de tamaño × Multiplicador de rareza × Variación individual (hoja Variación), redondeado. Se calcula en la hoja IE1, columnas K a P.
A24: Las celdas en azul son editables: cambia cualquier número y todos los jugadores de IE1 se recalculan solos.
A25: Vida = vida máxima · Ataque = daño del disparo básico · Ataque especial = daño de Q, E y R · Defensa = reducción plana de daño recibido · Velocidad = velocidad de movimiento (100 = referencia) · Regate = probabilidad de esquivar.
A26: Los valores concretos son una propuesta inicial mía (no vienen de ninguna fuente oficial): están pensados para equilibrarlos jugando.
A28: Escala de las barras (valor que llena la barra al 100 %) · en Regate es además el tope máximo
A29: Escala | B29: Vida | C29: Ataque | D29: Ataque especial | E29: Defensa | F29: Velocidad | G29: Regate
A30: Máximo | B30: 220 | C30: 25 | D30: 40 | E30: 15 | F30: 140 | G30: 0.1
A31: Las barras de la hoja Ficha usan esta escala. Las barras de las columnas K-P de IE1 usan los mismos valores fijos (si los cambias aquí, cámbialos también en Formato condicional de IE1). El Regate de ningún jugador puede superar el valor de la columna Regate de esta tabla (tope).

Sheet Variación
A1: Variación individual por jugador (multiplicador sobre la fórmula base posición × tamaño × rareza)
A2: Player HEX ID | B2: Jugador | C2: Vida | D2: Ataque | E2: Ataque especial | F2: Defensa | G2: Velocidad | H2: Regate
A3: 0x01 | B3: Mark Evans | C3: 1.12 | D3: 1.3 | E3: 1.2 | F3: 1.15 | G3: 1.05 | H3: 1
A4: 0x02 | B4: Nathan Swift | C4: 0.95 | D4: 0.95 | E4: 0.95 | F4: 0.97 | G4: 1.15 | H4: 1.15
A5: 0x03 | B5: Jack Wallside | C5: 1.08 | D5: 0.95 | E5: 0.9 | F5: 1.12 | G5: 0.95 | H5: 0.9
A6: 0x04 | B6: Jim Wraith | C6: 1.03 | D6: 0.95 | E6: 0.99 | F6: 0.92 | G6: 1.07 | H6: 1.05
A7: 0x05 | B7: Tod Ironside | C7: 1.05 | D7: 1.06 | E7: 1.01 | F7: 1.1 | G7: 0.97 | H7: 1.02
A8: 0x06 | B8: Steve Grim | C8: 1 | D8: 1.09 | E8: 1.1 | F8: 1.01 | G8: 1 | H8: 0.97
A9: 0x07 | B9: Tim Saunders | C9: 0.96 | D9: 1.06 | E9: 1.02 | F9: 0.99 | G9: 0.94 | H9: 0.92
A10: 0x08 | B10: Sam Kincaid | C10: 0.9 | D10: 1.01 | E10: 0.91 | F10: 0.93 | G10: 1.01 | H10: 1.04
A11: 0x09 | B11: Maxwell Carson | C11: 1.05 | D11: 1.02 | E11: 0.92 | F11: 1.06 | G11: 1.03 | H11: 1.04
A12: 0x0A | B12: Axel Blaze | C12: 0.95 | D12: 1.02 | E12: 1 | F12: 0.92 | G12: 1.08 | H12: 1.03
